Workbook

Sheet PES
A1: Variante: /POSIÇÃO.GER
A3: Material | B3: Centro | C3: Depósito | D3: Tipo de estoque | E3: Lote | F3: Estoque especial | G3: Nº estoque especial | H3: Texto breve material | I3: Tipo de depósito | J3: Posição no depósito | K3: Estoque disponível | L3: Unid.medida básica | M3: Data da entrada de mercadorias | N3: Data do vencimento | O3: Ár.armazen.
A4: 5003081800000596 | B4: 1003 | C4: SEXP | E4: 0550077485 | H4: VERDE FOLHAS LÍQUIDO - CORANTE ARTIFIC | I4: PES | J4: AJUSTE | K4: 0.12 | L4: kg | M4: 45838 | N4: 46855 | O4: GER
A5: 5028134600010700 | B5: 1003 | C5: SEXP | D5: S | E5: 0550077755 | H5: VERMELHO PEN - GEL PARA ESCREVER DE GR | I5: PES | J5: AJUSTE | K5: 1.08 | L5: kg | M5: 45884 | N5: 46150 | O5: GER
A6: 5053005200070584 | B6: 1003 | C6: SEXP | E6: 0550077130 | H6: AMARELO SOFTGEL CLASSIC - CORANTE ARTI | I6: PES | J6: AJUSTE | K6: 1.65 | L6: kg | M6: 45772 | N6: 46483 | O6: GER
A7: 5053045400020584 | B7: 1003 | C7: SEXP | E7: 0550084574 | H7: LARANJA SOFTGEL - CORANTE ARTIFICIAL D | I7: PES | J7: AJUSTE | K7: 0.15 | L7: kg | M7: 45985 | N7: 46694 | O7: GER
A8: 5053081800010584 | B8: 1003 | C8: SEXP | E8: 0550084995 | H8: VERDE FOLHAS SOFTGEL - MISTURA DE CORA | I8: PES | J8: AJUSTE | K8: 1.35 | L8: kg | M8: 45993 | N8: 46705 | O8: GER
A9: 5053130100000584 | B9: 1003 | C9: SEXP | E9: 0550084461 | H9: AMARELO DAMASCO SOFTGEL - CORANTE ARTI | I9: PES | J9: AJUSTE | K9: 0.3 | L9: kg | M9: 45979 | N9: 46691 | O9: GER
A10: 5053130200010584 | B10: 1003 | C10: SEXP | E10: 0550084255 | H10: AMARELO GEMA SOFTGEL - MISTURA DE CORA | I10: PES | J10: AJUSTE | K10: 3.6 | L10: kg | M10: 45978 | N10: 46686 | O10: GER
A11: 5053130200010584 | B11: 1003 | C11: SEXP | E11: 0550084997 | H11: AMARELO GEMA SOFTGEL - MISTURA DE CORA | I11: PES | J11: AJUSTE | K11: 0.45 | L11: kg | M11: 45992 | N11: 46705 | O11: GER
A12: 5053130200010584 | B12: 1003 | C12: SEXP | E12: 0550083671 | H12: AMARELO GEMA SOFTGEL - MISTURA DE CORA | I12: PES | J12: AJUSTE | K12: 0.15 | L12: kg | M12: 45996 | N12: 46673 | O12: GER
A13: 5053130400010584 | B13: 1003 | C13: SEXP | E13: 0550084753 | H13: AZUL ANIS SOFTGEL - MISTURA DE CORANTE | I13: PES | J13: AJUSTE | K13: 0.15 | L13: kg | M13: 45987 | N13: 46699 | O13: GER
A14: 5053130500000584 | B14: 1003 | C14: SEXP | E14: 0550083503 | H14: AZUL BEBÊ SOFTGEL - MISTURA DE CORANTE | I14: PES | J14: AJUSTE | K14: 0.15 | L14: kg | M14: 45975 | N14: 46667 | O14: GER
A15: 5053130800020584 | B15: 1003 | C15: SEXP | E15: 0550083094 | H15: BRANCO SOFTGEL CLASSIC - CORANTE ARTIF | I15: PES | J15: AJUSTE | K15: 1.2 | L15: kg | M15: 45941 | N15: 46657 | O15: GER
A16: 5053132800020584 | B16: 1003 | C16: SEXP | E16: 0550084009 | H16: PINK SOFTGEL - MISTURA DE CORANTES ART | I16: PES | J16: AJUSTE | K16: 0.15 | L16: kg | M16: 45996 | N16: 46681 | O16: GER
A17: 5053132800020584 | B17: 1003 | C17: SEXP | E17: 0550084462 | H17: PINK SOFTGEL - MISTURA DE CORANTES ART | I17: PES | J17: AJUSTE | K17: 0.45 | L17: kg | M17: 45981 | N17: 46691 | O17: GER
... A29: 5053193900000584 | B29: 1003 | C29: SEXP | E29: 0550084018 | H29: VERMELHO NOEL SOFTGEL - CORANTE ARTIFI | I29: PES | J29: AJUSTE | K29: 1.2 | L29: kg | M29: 45972 | N29: 46681 | O29: GER
A30: 5085032400470595 | B30: 1003 | C30: SEXP | D30: S | E30: 0550075888 | H30: DOCE DE LEITE MIX LIPO - AROMA ARTIFIC | I30: PES | J30: AJUSTE | K30: 0.334 | L30: kg | M30: 45728 | N30: 46082 | O30: GER
A31: 5085032400470595 | B31: 1003 | C31: SEXP | D31: S | E31: 0550076644 | H31: DOCE DE LEITE MIX LIPO - AROMA ARTIFIC | I31: PES | J31: AJUSTE | K31: 8.058 | L31: kg | M31: 45746 | N31: 46101 | O31: GER
A32: 5085061000050595 | B32: 1003 | C32: SEXP | D32: S | E32: 0550076640 | H32: PÃO DE MEL MIX LIPO - AROMA IDÊNTICO A | I32: PES | J32: AJUSTE | K32: 0.812 | L32: kg | M32: 45746 | N32: 46101 | O32: GER
A33: 5085118400080595 | B33: 1003 | C33: SEXP | E33: 0550077810 | H33: TORTA DE LIMÃO MIX LIPO - AROMA ARTIFI | I33: PES | J33: AJUSTE | K33: 0.107 | L33: kg | M33: 45803 | N33: 46152 | O33: GER
A34: 5003045400000596 | B34: 1003 | C34: SEXP | E34: 0550087024 | H34: LARANJA LÍQUIDO - CORANTE ARTIFICIAL D | I34: PES | J34: CORAN-021 | K34: 95.4 | L34: kg | M34: 46057 | N34: 47131 | O34: GER
A35: 5003130100000596 | B35: 1003 | C35: SEXP | E35: 0550087201 | H35: AMARELO DAMASCO LÍQUIDO - CORANTE ARTI | I35: PES | J35: CORAN-021 | K35: 92.64 | L35: kg | M35: 46062 | N35: 47137 | O35: GER
A36: 5003130200010596 | B36: 1003 | C36: SEXP | E36: 0550087364 | H36: AMARELO GEMA LÍQUIDO - CORANTE ARTIFIC | I36: PES | J36: CORAN-021 | K36: 92.52 | L36: kg | M36: 46072 | N36: 47143 | O36: GER
A37: 5003130400000596 | B37: 1003 | C37: SEXP | E37: 0550086116 | H37: AZUL ANIS LÍQUIDO - MISTURA DE CORANTE | I37: PES | J37: CORAN-021 | K37: 99.84 | L37: kg | M37: 46037 | N37: 47100 | O37: GER
A38: 5003130600000596 | B38: 1003 | C38: SEXP | E38: 0550086121 | H38: AZUL JEANS LÍQUIDO - CORANTE ARTIFICIA | I38: PES | J38: CORAN-021 | K38: 47.76 | L38: kg | M38: 46036 | N38: 47100 | O38: GER
A39: 5003132000000596 | B39: 1003 | C39: SEXP | E39: 0550087199 | H39: MARROM CHOCOLATE LÍQUIDO - CORANTE ART | I39: PES | J39: CORAN-021 | K39: 66 | L39: kg | M39: 46065 | N39: 47137 | O39: GER
A40: 5003132800000596 | B40: 1003 | C40: SEXP | E40: 0550085009 | H40: PINK LÍQUIDO - CORANTE ARTIFICIAL DE G | I40: PES | J40: CORAN-021 | K40: 0.48 | L40: kg | M40: 45996 | N40: 47065 | O40: GER
A41: 5003133600000596 | B41: 1003 | C41: SEXP | E41: 0550085012 | H41: ROSA CEREJA LÍQUIDO - MISTURA DE CORAN | I41: PES | J41: CORAN-021 | K41: 0.36 | L41: kg | M41: 46000 | N41: 47065 | O41: GER
A42: 5003133600000596 | B42: 1003 | C42: SEXP | E42: 0550086501 | H42: ROSA CEREJA LÍQUIDO - MISTURA DE CORAN | I42: PES | J42: CORAN-021 | K42: 1.92 | L42: kg | M42: 46038 | N42: 47115 | O42: GER
A43: 5003133900010596 | B43: 1003 | C43: SEXP | E43: 0550084308 | H43: ROXO BATATA LÍQUIDO - CORANTE ARTIFICI | I43: PES | J43: CORAN-021 | K43: 0.6 | L43: kg | M43: 45979 | N43: 47047 | O43: GER
A44: 5003134900000596 | B44: 1003 | C44: SEXP | E44: 0550087363 | H44: VERMELHO MORANGO LÍQUIDO - CORANTE ART | I44: PES | J44: CORAN-021 | K44: 136.56 | L44: kg | M44: 46072 | N44: 47143 | O44: GER
... A57: 5053045400020751 | B57: 1003 | C57: SEXP | E57: 0550084027 | H57: LARANJA SOFTGEL - CORANTE ARTIFICIAL D | I57: PES | J57: CORAN-021 | K57: 0.9 | L57: kg | M57: 45968 | N57: 46681 | O57: GER
A58: 5053071200010594 | B58: 1003 | C58: SEXP | D58: S | E58: 0550067337 | H58: ROSA GEL - CORANTE ARTIFICIAL PARA FIN | I58: PES | J58: CORAN-021 | K58: 0.36 | L58: kg | M58: 45660 | N58: 46134 | O58: GER
A59: 5053071200030584 | B59: 1003 | C59: SEXP | E59: 0550083508 | H59: ROSA SOFTGEL CLASSIC - CORANTE ARTIFIC | I59: PES | J59: CORAN-021 | K59: 0.9 | L59: kg | M59: 45957 | N59: 46667 | O59: GER
A60: 5053081800010700 | B60: 1003 | C60: SEXP | E60: 0550085759 | H60: VERDE FOLHAS SOFTGEL - CORANTE ARTIFIC | I60: PES | J60: CORAN-021 | K60: 155.52 | L60: kg | M60: 46013 | N60: 46720 | O60: GER
A61: 5053130100000584 | B61: 1003 | C61: SEXP | E61: 0550087034 | H61: AMARELO DAMASCO SOFTGEL - CORANTE ARTI | I61: PES | J61: CORAN-021 | K61: 234.9 | L61: kg | M61: 46065 | N61: 46771 | O61: GER
A62: 5053130100000700 | B62: 1003 | C62: SEXP | E62: 0550086631 | H62: AMARELO DAMASCO SOFTGEL - CORANTE ARTI | I62: PES | J62: CORAN-021 | K62: 110.88 | L62: kg | M62: 46044 | N62: 46757 | O62: GER
A63: 5053130200010700 | B63: 1003 | C63: SEXP | E63: 0550086767 | H63: AMARELO GEMA SOFTGEL - CORANTE ARTIFIC | I63: PES | J63: CORAN-021 | K63: 240.48 | L63: kg | M63: 46062 | N63: 46763 | O63: GER
A64: 5053130200010700 | B64: 1003 | C64: SEXP | E64: 0550084260 | H64: AMARELO GEMA SOFTGEL - CORANTE ARTIFIC | I64: PES | J64: CORAN-021 | K64: 0.72 | L64: kg | M64: 45974 | N64: 46686 | O64: GER
...

Sheet PIK
A1: Variante:estoque geral
A3: Material | B3: Centro | C3: Depósito | D3: Tipo de estoque | E3: Lote | F3: Estoque especial | G3: Nº estoque especial | H3: Texto breve material | I3: Tipo de depósito | J3: Posição no depósito | K3: Estoque disponível | L3: Unid.medida básica | M3: Data da entrada de mercadorias | N3: Data do vencimento | O3: Ár.armazen.
A4: 5085118400080595 | B4: 1003 | C4: SEXP | E4: 0550077810 | H4: TORTA DE LIMÃO MIX LIPO - AROMA ARTIFI | I4: PIK | J4: J-01-001 | K4: 3.296 | L4: kg | M4: 45803 | N4: 46152 | O4: GER
A5: 5085230400000595 | B5: 1003 | C5: SEXP | E5: 0550079702 | H5: PÉ DE MOLEQUE MIX - AROMA ARTIFICIAL D | I5: PIK | J5: J-01-001 | K5: 19.152 | L5: kg | M5: 45863 | N5: 46569 | O5: GER
A6: 5032203000000787 | B6: 1003 | C6: SEXP | E6: 0550075242 | H6: VERDE ÁGUA CORANTE EM PÓ LIPOSSOLÚVEL | I6: PIK | J6: J-01-003 | K6: 8.46 | L6: kg | M6: 45703 | N6: 46420 | O6: GER
A7: 5085229600000595 | B7: 1003 | C7: SEXP | E7: 0550079699 | H7: PIPOCA CARAMELIZADA MIX - AROMA ARTIFI | I7: PIK | J7: J-01-004 | K7: 23.424 | L7: kg | M7: 45856 | N7: 46569 | O7: GER
A8: 5085229600000595 | B8: 1003 | C8: SEXP | D8: S | E8: 0550078293 | H8: PIPOCA CARAMELIZADA MIX - AROMA ARTIFI | I8: PIK | J8: J-01-004 | K8: 0.168 | L8: kg | M8: 45810 | N8: 46525 | O8: GER
A9: 5085229600000595 | B9: 1003 | C9: SEXP | E9: 0550078293 | H9: PIPOCA CARAMELIZADA MIX - AROMA ARTIFI | I9: PIK | J9: J-01-004 | K9: 0.336 | L9: kg | M9: 45996 | N9: 46525 | O9: GER
A10: 5085230400000595 | B10: 1003 | C10: SEXP | E10: 0550079702 | H10: PÉ DE MOLEQUE MIX - AROMA ARTIFICIAL D | I10: PIK | J10: J-01-005 | K10: 13.44 | L10: kg | M10: 45863 | N10: 46569 | O10: GER
A11: 5085045400460595 | B11: 1003 | C11: SEXP | E11: 0550087563 | H11: LARANJA MIX LIPO - AROMA ARTIFICIAL DE | I11: PIK | J11: J-01-006 | K11: 16.974 | L11: kg | M11: 46073 | N11: 46432 | O11: GER
A12: 5085083200280595 | B12: 1003 | C12: SEXP | E12: 0550082109 | H12: FRUTAS VERMELHAS MIX - AROMA ARTIFICIA | I12: PIK | J12: J-01-006 | K12: 34.272 | L12: kg | M12: 45918 | N12: 46629 | O12: GER
A13: 5085058200050595 | B13: 1003 | C13: SEXP | E13: 0550078294 | H13: MILHO VERDE MIX - AROMA ARTIFICIAL DE | I13: PIK | J13: J-01-007 | K13: 0.468 | L13: kg | M13: 45674 | N13: 46525 | O13: GER
A14: 5085058200050595 | B14: 1003 | C14: SEXP | E14: 0550078812 | H14: MILHO VERDE MIX - AROMA ARTIFICIAL DE | I14: PIK | J14: J-01-007 | K14: 0.372 | L14: kg | M14: 46008 | N14: 46539 | O14: GER
A15: 5085056600270595 | B15: 1003 | C15: SEXP | E15: 0550086101 | H15: MENTA MIX LIPO - AROMA IDÊNTICO AO NAT | I15: PIK | J15: J-01-008 | K15: 17.84 | L15: kg | M15: 46027 | N15: 46380 | O15: GER
A16: 5085047600210595 | B16: 1003 | C16: SEXP | E16: 0550086234 | H16: LEITE CONDENSADO MIX LIPO - AROMA ARTI | I16: PIK | J16: J-01-009 | K16: 6.21 | L16: kg | M16: 46036 | N16: 46389 | O16: GER
A17: 5085047600210595 | B17: 1003 | C17: SEXP | E17: 0550086263 | H17: LEITE CONDENSADO MIX LIPO - AROMA ARTI | I17: PIK | J17: J-01-009 | K17: 1.656 | L17: kg | M17: 46036 | N17: 46391 | O17: GER
A18: 5085222900000595 | B18: 1003 | C18: SEXP | E18: 0550086232 | H18: CARAMELO TOFFEE MIX LIPO - AROMA ARTIF | I18: PIK | J18: J-01-010 | K18: 13.695 | L18: kg | M18: 46035 | N18: 46389 | O18: GER
A19: 5085067600050595 | B19: 1003 | C19: SEXP | E19: 0550085098 | H19: PISTACHE MIX LIPO - AROMA ARTIFICIAL D | I19: PIK | J19: J-01-011 | K19: 5.81 | L19: kg | M19: 45994 | N19: 46347 | O19: GER
A20: 5085032400470595 | B20: 1003 | C20: SEXP | E20: 0550086992 | H20: DOCE DE LEITE MIX LIPO - AROMA ARTIFIC | I20: PIK | J20: J-01-012 | K20: 24.426 | L20: kg | M20: 46058 | N20: 46410 | O20: GER
... A56: 5032133600010787 | B56: 1003 | C56: SEXP | E56: 0550082916 | H56: ROSA CEREJA PÓ - MISTURA DE CORANTES A | I56: PIK | J56: PD-03-007 | K56: 3.72 | L56: kg | M56: 45940 | N56: 47012 | O56: GER
A57: 5032134200000787 | B57: 1003 | C57: SEXP | D57: S | E57: 0550073139 | H57: VERDE BANDEIRA CORANTE EM PÓ LIPOSSOL | I57: PIK | J57: PD-03-007 | K57: 0.06 | L57: kg | M57: 45660 | N57: 46338 | O57: GER
A58: 5032133000020670 | B58: 1003 | C58: SEXP | E58: 0550084485 | H58: PRETO PÓ - CORANTE ARTIFICIAL PARA FIN | I58: PIK | J58: PD-03-008 | K58: 6.3 | L58: kg | M58: 45979 | N58: 47052 | O58: GER
A59: 5032133300000787 | B59: 1003 | C59: SEXP | E59: 0550082516 | H59: PRETO INTENSO PÓ - CORANTE ARTIFICIAL | I59: PIK | J59: PD-03-009 | K59: 7.44 | L59: kg | M59: 45927 | N59: 47004 | O59: GER
A60: 5032130100000787 | B60: 1003 | C60: SEXP | E60: 0550086734 | H60: AMARELO DAMASCO PÓ - CORANTE ARTIFICIA | I60: PIK | J60: PD-03-010 | K60: 7.02 | L60: kg | M60: 46057 | N60: 47122 | O60: GER
A61: 5053134400000594 | B61: 1003 | C61: SEXP | E61: 0550072853 | H61: VERDE HORTELÃ GEL - CORANTE ARTIFICIAL | I61: PIK | J61: PD-04-002 | K61: 31.5 | L61: kg | M61: 45629 | N61: 46330 | O61: GER
A62: 5032135300000787 | B62: 1003 | C62: SEXP | E62: 0550083647 | H62: VINHO BORDÔ PÓ - CORANTE ARTIFICIAL DE | I62: PIK | J62: PD-04-003 | K62: 6.72 | L62: kg | M62: 45967 | N62: 47032 | O62: GER
A63: 5032132000000787 | B63: 1003 | C63: SEXP | E63: 0550083482 | H63: MARROM CHOCOLATE PÓ - CORANTE ARTIFICI | I63: PIK | J63: PD-04-004 | K63: 5.82 | L63: kg | M63: 45967 | N63: 47026 | O63: GER
A64: 5032045400010670 | B64: 1003 | C64: SEXP | E64: 0550085774 | H64: LARANJA PÓ - CORANTE ARTIFICIAL PARA F | I64: PIK | J64: PD-04-005 | K64: 5.94 | L64: kg | M64: 46008 | N64: 47080 | O64: GER
A65: 5032135400000670 | B65: 1003 | C65: SEXP | E65: 0550084708 | H65: VIOLETA PÓ - CORANTE ARTIFICIAL PARA F | I65: PIK | J65: PD-04-006 | K65: 3.816 | L65: kg | M65: 45996 | N65: 47058 | O65: GER
A66: 5032205300000670 | B66: 1003 | C66: SEXP | E66: 0550073688 | H66: AZUL GELADINHO BECA - AVELUDADO - CORA | I66: PIK | J66: PD-04-006 | K66: 0.72 | L66: kg | M66: 45660 | N66: 46710 | O66: GER
A67: 5053205800000584 | B67: 1003 | C67: SEXP | D67: S | E67: 0550067844 | H67: LARANJA TANGERINA BECA - SOFTGEL - COR | I67: PIK | J67: PD-04-006 | K67: 2.85 | L67: kg | M67: 45838 | N67: 46153 | O67: GER
A68: 5032205900000670 | B68: 1003 | C68: SEXP | E68: 0550064567 | H68: AMARELO CARAMELO BECA - AVELUDADO - CO | I68: PIK | J68: PD-04-007 | K68: 1.512 | L68: kg | M68: 45660 | N68: 46355 | O68: GER
A69: 5032206000000670 | B69: 1003 | C69: SEXP | E69: 0550069257 | H69: CINZA SUSPIRO BECA - AVELUDADO - CORAN | I69: PIK | J69: PD-04-007 | K69: 0.576 | L69: kg | M69: 45660 | N69: 46565 | O69: GER
A70: 5032050100000670 | B70: 1003 | C70: SEXP | E70: 0550083257 | H70: MAÇÃ VERDE PÓ - CORANTE ARTIFICIAL PAR | I70: PIK | J70: PD-04-008 | K70: 3.204 | L70: kg | M70: 45950 | N70: 47020 | O70: GER
A71: 5032133900000787 | B71: 1003 | C71: SEXP | E71: 0550084585 | H71: ROXO BATATA PÓ - CORANTE ARTIFICIAL DE | I71: PIK | J71: PD-04-009 | K71: 11.04 | L71: kg | M71: 45993 | N71: 47054 | O71: GER
A72: 5032133900000787 | B72: 1003 | C72: SEXP | E72: 0550082316 | H72: ROXO BATATA PÓ - CORANTE ARTIFICIAL DE | I72: PIK | J72: PD-04-009 | K72: 0.9 | L72: kg | M72: 45923 | N72: 46997 | O72: GER
A73: 5032134900000787 | B73: 1003 | C73: SEXP | E73: 0550084560 | H73: VERMELHO MORANGO PÓ - CORANTE ARTIFICI | I73: PIK | J73: PD-04-010 | K73: 5.58 | L73: kg | M73: 45985 | N73: 47053 | O73: GER
A74: 5032133900000349 | B74: 1003 | C74: SEXP | E74: 0550084586 | H74: ROXO BATATA PÓ - CORANTE ARTIFICIAL DE | I74: PIK | J74: PE-01-001 | K74: 2.5 | L74: kg | M74: 45979 | N74: 47054 | O74: GER
A75: 5032135300000349 | B75: 1003 | C75: SEXP | E75: 0550086006 | H75: VINHO BORDÔ PÓ - CORANTE ARTIFICIAL DE | I75: PIK | J75: PE-01-002 | K75: 36 | L75: kg | M75: 46009 | N75: 47087 | O75: GER
A76: 5032130200000349 | B76: 1003 | C76: SEXP | E76: 0550086004 | H76: AMARELO GEMA PÓ - CORANTE ARTIFICIAL D | I76: PIK | J76: PE-02-001 | K76: 10.5 | L76: kg | M76: 46009 | N76: 47087 | O76: GER
...

Sheet Ressuprimento 1
B2: Vaga PG | C2: Material | D2: Nome Material | E2: Saldo PIK | F2: Peso Min | G2: Prox/Atual | H2: Lote | I2: Saldo PES
B3: PG-01-001 | C3: 5053135000010584 | D3: VERMELHO NATAL SOFTGEL - MISTURA DE CO | E3: =VALUE(SUMIFS(Tabela4[Estoque disponível],Tabela4[Material],'Ressuprimento 1'!C3)) -> 23.7 | F3: 12 | G3: J-01-003 | H3: 0550085138 | I3: =SUMIFS(Tabela1[Estoque disponível],Tabela1[Posição no depósito],Tabela2[[#This Row],[Prox/Atual]],Tabela1[Lote],Tabela2[[#This Row],[Lote]]) -> 108
B4: PG-01-002 | C4: 5053133300000584 | D4: PRETO INTENSO SOFTGEL - MISTURA DE COR | E4: =VALUE(SUMIFS(Tabela4[Estoque disponível],Tabela4[Material],'Ressuprimento 1'!C4)) -> 104.25 | F4: 12 | G4: K-04-007 | H4: 0550086254 | I4: =SUMIFS(Tabela1[Estoque disponível],Tabela1[Posição no depósito],Tabela2[[#This Row],[Prox/Atual]],Tabela1[Lote],Tabela2[[#This Row],[Lote]]) -> 271.35
B5: PG-01-003 | C5: 5053130200010584 | D5: AMARELO GEMA SOFTGEL - MISTURA DE CORA | E5: =VALUE(SUMIFS(Tabela4[Estoque disponível],Tabela4[Material],'Ressuprimento 1'!C5)) -> 88.95 | F5: 12 | G5: J-01-009 | H5: 0550086472 | I5: =SUMIFS(Tabela1[Estoque disponível],Tabela1[Posição no depósito],Tabela2[[#This Row],[Prox/Atual]],Tabela1[Lote],Tabela2[[#This Row],[Lote]]) -> 36
B6: PG-01-004 | C6: 5053132800020584 | D6: PINK SOFTGEL - MISTURA DE CORANTES ART | E6: =VALUE(SUMIFS(Tabela4[Estoque disponível],Tabela4[Material],'Ressuprimento 1'!C6)) -> 18.6 | F6: 12 | G6: J-01-005 | H6: 0550085293 | I6: =SUMIFS(Tabela1[Estoque disponível],Tabela1[Posição no depósito],Tabela2[[#This Row],[Prox/Atual]],Tabela1[Lote],Tabela2[[#This Row],[Lote]]) -> 88.2
B7: PG-01-005 | C7: 5053134500010584 | D7: VERDE LIMÃO SOFTGEL - CORANTE ARTIFICI | E7: =VALUE(SUMIFS(Tabela4[Estoque disponível],Tabela4[Material],'Ressuprimento 1'!C7)) -> 120 | F7: 12 | G7: K-03-030 | H7: 0550086764 | I7: =SUMIFS(Tabela1[Estoque disponível],Tabela1[Posição no depósito],Tabela2[[#This Row],[Prox/Atual]],Tabela1[Lote],Tabela2[[#This Row],[Lote]]) -> 262.5
B8: PG-01-006 | C8: 5053135500000584 | D8: ROSA INTENSO SOFTGEL - CORANTE ARTIFIC | E8: =VALUE(SUMIFS(Tabela4[Estoque disponível],Tabela4[Material],'Ressuprimento 1'!C8)) -> 92.55 | F8: 12 | G8: J-01-004 | H8: 0550085294 | I8: =SUMIFS(Tabela1[Estoque disponível],Tabela1[Posição no depósito],Tabela2[[#This Row],[Prox/Atual]],Tabela1[Lote],Tabela2[[#This Row],[Lote]]) -> 135.6
B9: PG-01-008 | C9: 5053081800010584 | D9: VERDE FOLHAS SOFTGEL - MISTURA DE CORA | E9: =VALUE(SUMIFS(Tabela4[Estoque disponível],Tabela4[Material],'Ressuprimento 1'!C9)) -> 13.95 | F9: 12 | G9: J-01-008 | H9: 0550085736 | I9: =SUMIFS(Tabela1[Estoque disponível],Tabela1[Posição no depósito],Tabela2[[#This Row],[Prox/Atual]],Tabela1[Lote],Tabela2[[#This Row],[Lote]]) -> 50.85
B10: PG-01-009 | C10: 5053130000030584 | D10: MARROM SOFTGEL - CORANTE ARTIFICIAL DE | E10: =VALUE(SUMIFS(Tabela4[Estoque disponível],Tabela4[Material],'Ressuprimento 1'!C10)) -> 52.35 | F10: 12 | G10: J-04-026 | H10: 0550086139 | I10: =SUMIFS(Tabela1[Estoque disponível],Tabela1[Posição no depósito],Tabela2[[#This Row],[Prox/Atual]],Tabela1[Lote],Tabela2[[#This Row],[Lote]]) -> 263.4
B12: PF 150G | C12: Material | D12: Nome Material | E12: peso atual | F12: Peso Min | G12: Prox/Atual | H12: Lote | I12: Saldo PES
B13: PF-01-001 | C13: 5053045400020584 | D13: LARANJA SOFTGEL - CORANTE ARTIFICIAL D | E13: =VALUE(SUMIFS(Tabela4[Estoque disponível],Tabela4[Material],'Ressuprimento 1'!C13)) -> 43.65 | F13: 12 | G13: CORAN-021 | H13: 0550085290 | I13: =SUMIFS(Tabela1[Estoque disponível],Tabela1[Posição no depósito],Tabela24[[#This Row],[Prox/Atual]],Tabela1[Lote],Tabela24[[#This Row],[Lote]]) -> 84
B14: PF-01-002 | C14: 5053130600010584 | D14: AZUL JEANS SOFTGEL - CORANTE ARTIFICIA | E14: =VALUE(SUMIFS(Tabela4[Estoque disponível],Tabela4[Material],'Ressuprimento 1'!C14)) -> 87.6 | F14: 12 | G14: J-04-007 | H14: 0550084755 | I14: =SUMIFS(Tabela1[Estoque disponível],Tabela1[Posição no depósito],Tabela24[[#This Row],[Prox/Atual]],Tabela1[Lote],Tabela24[[#This Row],[Lote]]) -> 271.5
B15: PF-01-003 | C15: 5053082000010584 | D15: VINHO SOFTGEL - CORANTE ARTIFICIAL DE | E15: =VALUE(SUMIFS(Tabela4[Estoque disponível],Tabela4[Material],'Ressuprimento 1'!C15)) -> 27.9 | F15: 12 | G15: J-01-009 | H15: 0550084465 | I15: =SUMIFS(Tabela1[Estoque disponível],Tabela1[Posição no depósito],Tabela24[[#This Row],[Prox/Atual]],Tabela1[Lote],Tabela24[[#This Row],[Lote]]) -> 35.4
B16: PF-01-004 | C16: 5053133600000584 | D16: ROSA CEREJA SOFTGEL - CORANTE ARTIFICI | E16: =VALUE(SUMIFS(Tabela4[Estoque disponível],Tabela4[Material],'Ressuprimento 1'!C16)) -> 40.65 | F16: 12 | G16: J-02-025 | H16: 0550086135 | I16: =SUMIFS(Tabela1[Estoque disponível],Tabela1[Posição no depósito],Tabela24[[#This Row],[Prox/Atual]],Tabela1[Lote],Tabela24[[#This Row],[Lote]]) -> 255.9
B17: PF-01-005 | C17: 5053135700000584 | D17: SUPER BRANCO SOFTGEL - CORANTE ARTIFIC | E17: =VALUE(SUMIFS(Tabela4[Estoque disponível],Tabela4[Material],'Ressuprimento 1'!C17)) -> 42.45 | F17: 12 | G17: J-01-007 | H17: 0550085549 | I17: =SUMIFS(Tabela1[Estoque disponível],Tabela1[Posição no depósito],Tabela24[[#This Row],[Prox/Atual]],Tabela1[Lote],Tabela24[[#This Row],[Lote]]) -> 102.3
B18: PF-01-006 | C18: 5053130400010584 | D18: AZUL ANIS SOFTGEL - MISTURA DE CORANTE | E18: =VALUE(SUMIFS(Tabela4[Estoque disponível],Tabela4[Material],'Ressuprimento 1'!C18)) -> 105.75 | F18: 12 | I18: =SUMIFS(Tabela1[Estoque disponível],Tabela1[Posição no depósito],Tabela24[[#This Row],[Prox/Atual]],Tabela1[Lote],Tabela24[[#This Row],[Lote]]) -> 0
B19: PF-01-007 | C19: 5053130500000584 | D19: AZUL BEBÊ SOFTGEL - MISTURA DE CORANTE | E19: =VALUE(SUMIFS(Tabela4[Estoque disponível],Tabela4[Material],'Ressuprimento 1'!C19)) -> 96.9 | F19: 12 | I19: =SUMIFS(Tabela1[Estoque disponível],Tabela1[Posição no depósito],Tabela24[[#This Row],[Prox/Atual]],Tabela1[Lote],Tabela24[[#This Row],[Lote]]) -> 0
B20: PF-01-008 | C20: 5053193900000584 | D20: VERMELHO NOEL SOFTGEL - CORANTE ARTIFI | E20: =VALUE(SUMIFS(Tabela4[Estoque disponível],Tabela4[Material],'Ressuprimento 1'!C20)) -> 67.65 | F20: 12 | I20: =SUMIFS(Tabela1[Estoque disponível],Tabela1[Posição no depósito],Tabela24[[#This Row],[Prox/Atual]],Tabela1[Lote],Tabela24[[#This Row],[Lote]]) -> 0
B21: PF-01-009 | C21: 5.0531434e+15 | D21: AZUL ROYAL SOFTGEL - CORANTE ARTIFICIA | E21: =VALUE(SUMIFS(Tabela4[Estoque disponível],Tabela4[Material],'Ressuprimento 1'!C21)) -> 68.25 | F21: 12 | I21: =SUMIFS(Tabela1[Estoque disponível],Tabela1[Posição no depósito],Tabela24[[#This Row],[Prox/Atual]],Tabela1[Lote],Tabela24[[#This Row],[Lote]]) -> 0
B23: Vaga PH 150G | C23: Material | D23: Nome Material | E23: peso atual | F23: Peso Min | G23: Prox/Atual | H23: Lote | I23: Saldo PES
B24: PH-01-042 | C24: 5053133500000584 | D24: ROSA BEBÊ SOFTGEL - CORANTE ARTIFICIAL | E24: =VALUE(SUMIFS(Tabela4[Estoque disponível],Tabela4[Material],'Ressuprimento 1'!C24)) -> 31.5 | F24: 12 | I24: =SUMIFS(Tabela1[Estoque disponível],Tabela1[Posição no depósito],Tabela2[[#This Row],[Prox/Atual]],Tabela1[Lote],Tabela2[[#This Row],[Lote]]) -> 0
B25: PH-01-044 | C25: 5053126500000584 | D25: VERDE MUSGO SOFTGEL - CORANTE ARTIFICI | E25: =VALUE(SUMIFS(Tabela4[Estoque disponível],Tabela4[Material],'Ressuprimento 1'!C25)) -> 66.3 | F25: 12 | I25: =SUMIFS(Tabela1[Estoque disponível],Tabela1[Posição no depósito],Tabela2[[#This Row],[Prox/Atual]],Tabela1[Lote],Tabela2[[#This Row],[Lote]]) -> 0
B26: PH-01-045 | C26: 5053133800000584 | D26: ROXO SOFTGEL - CORANTE ARTIFICIAL DE G | E26: =VALUE(SUMIFS(Tabela4[Estoque disponível],Tabela4[Material],'Ressuprimento 1'!C26)) -> 92.25 | F26: 12 | I26: =SUMIFS(Tabela1[Estoque disponível],Tabela1[Posição no depósito],Tabela2[[#This Row],[Prox/Atual]],Tabela1[Lote],Tabela2[[#This Row],[Lote]]) -> 0
B27: PH-01-046 | C27: 5053130100000584 | D27: AMARELO DAMASCO SOFTGEL - CORANTE ARTI | E27: =VALUE(SUMIFS(Tabela4[Estoque disponível],Tabela4[Material],'Ressuprimento 1'!C27)) -> 55.65 | F27: 12 | I27: =SUMIFS(Tabela1[Estoque disponível],Tabela1[Posição no depósito],Tabela2[[#This Row],[Prox/Atual]],Tabela1[Lote],Tabela2[[#This Row],[Lote]]) -> 0
B28: PH-01-047 | C28: 5053134400010584 | D28: VERDE HORTELÃ SOFTGEL - MISTURA DE COR | E28: =VALUE(SUMIFS(Tabela4[Estoque disponível],Tabela4[Material],'Ressuprimento 1'!C28)) -> 65.85 | F28: 12 | I28: =SUMIFS(Tabela1[Estoque disponível],Tabela1[Posição no depósito],Tabela2[[#This Row],[Prox/Atual]],Tabela1[Lote],Tabela2[[#This Row],[Lote]]) -> 0
B29: PH-01-048 | C29: 5053114300000584 | D29: LILÁS SOFTGEL - MISTURA DE CORANTES AR | E29: =VALUE(SUMIFS(Tabela4[Estoque disponível],Tabela4[Material],'Ressuprimento 1'!C29)) -> 33.9 | F29: 12 | I29: =SUMIFS(Tabela1[Estoque disponível],Tabela1[Posição no depósito],Tabela2[[#This Row],[Prox/Atual]],Tabela1[Lote],Tabela2[[#This Row],[Lote]]) -> 0
B30: PH-01-049 | C30: 5053134900010584 | D30: VERMELHO MORANGO SOFTGEL - CORANTE ART | E30: =VALUE(SUMIFS(Tabela4[Estoque disponível],Tabela4[Material],'Ressuprimento 1'!C30)) -> 137.55 | F30: 12 | I30: =SUMIFS(Tabela1[Estoque disponível],Tabela1[Posição no depósito],Tabela2[[#This Row],[Prox/Atual]],Tabela1[Lote],Tabela2[[#This Row],[Lote]]) -> 0
B31: PH-01-050 | C31: 5053130700000584 | D31: AZUL MARINHO SOFTGEL - CORANTE ARTIFIC | E31: =VALUE(SUMIFS(Tabela4[Estoque disponível],Tabela4[Material],'Ressuprimento 1'!C31)) -> 60 | F31: 12 | I31: =SUMIFS(Tabela1[Estoque disponível],Tabela1[Posição no depósito],Tabela2[[#This Row],[Prox/Atual]],Tabela1[Lote],Tabela2[[#This Row],[Lote]]) -> 0
B32: PH-01-051 | C32: 5053135400000584 | D32: VIOLETA SOFTGEL - MISTURA DE CORANTES | E32: =VALUE(SUMIFS(Tabela4[Estoque disponível],Tabela4[Material],'Ressuprimento 1'!C32)) -> 94.05 | F32: 12 | I32: =SUMIFS(Tabela1[Estoque disponível],Tabela1[Posição no depósito],Tabela2[[#This Row],[Prox/Atual]],Tabela1[Lote],Tabela2[[#This Row],[Lote]]) -> 0
B34: SOFT 360 | C34: Material | D34: Nome Material | E34: peso atual | F34: Peso Min | G34: Prox/Atual | H34: Lote | I34: Saldo PES
B35: PF-01-030 | C35: 5053134000000700 | D35: TURQUESA SOFTGEL - CORANTE ARTIFICIAL | E35: =VALUE(SUMIFS(Tabela4[Estoque disponível],Tabela4[Material],'Ressuprimento 1'!C35)) -> 54.36 | F35: 18 | I35: =SUMIFS(Tabela1[Estoque disponível],Tabela1[Posição no depósito],Tabela2[[#This Row],[Prox/Atual]],Tabela1[Lote],Tabela2[[#This Row],[Lote]]) -> 0
B36: PF-01-031 | C36: 5.0531307e+15 | D36: AZUL MARINHO SOFTGEL - CORANTE ARTIFIC | E36: =VALUE(SUMIFS(Tabela4[Estoque disponível],Tabela4[Material],'Ressuprimento 1'!C36)) -> 92.16 | F36: 18 | I36: =SUMIFS(Tabela1[Estoque disponível],Tabela1[Posição no depósito],Tabela2[[#This Row],[Prox/Atual]],Tabela1[Lote],Tabela2[[#This Row],[Lote]]) -> 0
B37: PF-01-032 | C37: 5.053135e+15 | D37: VERMELHO NATAL SOFTGEL - CORANTE ARTIF | E37: =VALUE(SUMIFS(Tabela4[Estoque disponível],Tabela4[Material],'Ressuprimento 1'!C37)) -> 53.28 | F37: 18 | I37: =SUMIFS(Tabela1[Estoque disponível],Tabela1[Posição no depósito],Tabela2[[#This Row],[Prox/Atual]],Tabela1[Lote],Tabela2[[#This Row],[Lote]]) -> 0
B38: PF-01-033 | C38: 5053081800010700 | D38: VERDE FOLHAS SOFTGEL - CORANTE ARTIFIC | E38: =VALUE(SUMIFS(Tabela4[Estoque disponível],Tabela4[Material],'Ressuprimento 1'!C38)) -> 25.92 | F38: 18 | I38: =SUMIFS(Tabela1[Estoque disponível],Tabela1[Posição no depósito],Tabela2[[#This Row],[Prox/Atual]],Tabela1[Lote],Tabela2[[#This Row],[Lote]]) -> 0
B39: PF-01-034 | C39: 5053130600010700 | D39: AZUL JEANS SOFTGEL - CORANTE ARTIFICIA | E39: =VALUE(SUMIFS(Tabela4[Estoque disponível],Tabela4[Material],'Ressuprimento 1'!C39)) -> 71.64 | F39: 18 | I39: =SUMIFS(Tabela1[Estoque disponível],Tabela1[Posição no depósito],Tabela2[[#This Row],[Prox/Atual]],Tabela1[Lote],Tabela2[[#This Row],[Lote]]) -> 0
B40: PF-01-035 | C40: 5053133300000700 | D40: PRETO INTENSO SOFTGEL - CORANTE ARTIFI | E40: =VALUE(SUMIFS(Tabela4[Estoque disponível],Tabela4[Material],'Ressuprimento 1'!C40)) -> 41.4 | F40: 18 | I40: =SUMIFS(Tabela1[Estoque disponível],Tabela1[Posição no depósito],Tabela2[[#This Row],[Prox/Atual]],Tabela1[Lote],Tabela2[[#This Row],[Lote]]) -> 0
B41: PF-01-036 | C41: 5053130200010700 | D41: AMARELO GEMA SOFTGEL - CORANTE ARTIFIC | E41: =VALUE(SUMIFS(Tabela4[Estoque disponível],Tabela4[Material],'Ressuprimento 1'!C41)) -> 29.88 | F41: 18 | I41: =SUMIFS(Tabela1[Estoque disponível],Tabela1[Posição no depósito],Tabela2[[#This Row],[Prox/Atual]],Tabela1[Lote],Tabela2[[#This Row],[Lote]]) -> 0
B42: PF-01-037 | C42: 5053134400010700 | D42: VERDE HORTELÃ SOFTGEL - CORANTE ARTIFI | E42: =VALUE(SUMIFS(Tabela4[Estoque disponível],Tabela4[Material],'Ressuprimento 1'!C42)) -> 20.88 | F42: 18 | I42: =SUMIFS(Tabela1[Estoque disponível],Tabela1[Posição no depósito],Tabela2[[#This Row],[Prox/Atual]],Tabela1[Lote],Tabela2[[#This Row],[Lote]]) -> 0
B43: PF-01-038 | C43: 5053133600000700 | D43: ROSA CEREJA SOFTGEL - CORANTE ARTIFICI | E43: =VALUE(SUMIFS(Tabela4[Estoque disponível],Tabela4[Material],'Ressuprimento 1'!C43)) -> 93.6 | F43: 18 | I43: =SUMIFS(Tabela1[Estoque disponível],Tabela1[Posição no depósito],Tabela2[[#This Row],[Prox/Atual]],Tabela1[Lote],Tabela2[[#This Row],[Lote]]) -> 0
B44: PF-01-039 | C44: 5053130000030700 | D44: MARROM SOFTGEL - CORANTE ARTIFICIAL DE | E44: =VALUE(SUMIFS(Tabela4[Estoque disponível],Tabela4[Material],'Ressuprimento 1'!C44)) -> 78.84 | F44: 18 | I44: =SUMIFS(Tabela1[Estoque disponível],Tabela1[Posição no depósito],Tabela2[[#This Row],[Prox/Atual]],Tabela1[Lote],Tabela2[[#This Row],[Lote]]) -> 0
...

Sheet Ressuprimento 2
B2: AROMAS | C2: Material | D2: Nome Material | E2: Saldo PIK | F2: Peso Min | G2: Prox/Atual | H2: Lote
B3: PI-01-001 | C3: 5085025700550595 | D3: COCO MIX - AROMA ARTIFICIAL DE | E3: =SUMIFS(Tabela4[Estoque disponível],Tabela4[Material],Tabela29[[#This Row],[Material]]) -> 86.04 | F3: 11.88
B4: PI-01-002 | C4: 5085060400120595 | D4: NOZES MIX - AROMA IDÊNTICO AO NATURAL | E4: =SUMIFS(Tabela4[Estoque disponível],Tabela4[Material],Tabela29[[#This Row],[Material]]) -> 46.08 | F4: 11.88
B5: PI-01-003 | C5: 5085062800230595 | D5: PANETONE MIX - AROMA ARTIFICIAL DE | E5: =SUMIFS(Tabela4[Estoque disponível],Tabela4[Material],Tabela29[[#This Row],[Material]]) -> 16.56 | F5: 11.88
B6: PI-01-004 | C6: 5085079600180595 | D6: TUTTI FRUTTI MIX - AROMA ARTIFICIAL DE | E6: =SUMIFS(Tabela4[Estoque disponível],Tabela4[Material],Tabela29[[#This Row],[Material]]) -> 38.52 | F6: 11.88
B7: PI-01-005 | C7: 5085052900720595 | D7: MANTEIGA MIX - AROMA ARTIFICIAL DE | E7: =SUMIFS(Tabela4[Estoque disponível],Tabela4[Material],Tabela29[[#This Row],[Material]]) -> 19.8 | F7: 11.88
B8: PI-01-006 | C8: 5085058501120595 | D8: MORANGO MIX - AROMA IDÊNTICO AO NATURA | E8: =SUMIFS(Tabela4[Estoque disponível],Tabela4[Material],Tabela29[[#This Row],[Material]]) -> 117.36 | F8: 11.88
B9: PI-01-007 | C9: 5085053200270595 | D9: MARACUJÁ MIX - AROMA IDÊNTICO AO NATUR | E9: =SUMIFS(Tabela4[Estoque disponível],Tabela4[Material],Tabela29[[#This Row],[Material]]) -> 46.44 | F9: 11.88
B10: PI-01-008 | C10: 5085053400220595 | D10: MARULA MIX - AROMA ARTIFICIAL DE | E10: =SUMIFS(Tabela4[Estoque disponível],Tabela4[Material],Tabela29[[#This Row],[Material]]) -> 70.92 | F10: 11.88
B11: PI-01-009 | C11: 5085048400410595 | D11: LIMÃO MIX - AROMA IDÊNTICO AO NATURAL | E11: =SUMIFS(Tabela4[Estoque disponível],Tabela4[Material],Tabela29[[#This Row],[Material]]) -> 14.4 | F11: 11.88
B12: PI-01-010 | C12: 5085024200480595 | D12: CHOCOLATE MIX - AROMA ARTIFICIAL DE | E12: =SUMIFS(Tabela4[Estoque disponível],Tabela4[Material],Tabela29[[#This Row],[Material]]) -> 76.68 | F12: 11.88
B13: PI-01-011 | C13: 5085011300300595 | D13: BANANA MIX - AROMA ARTIFICIAL DE | E13: =SUMIFS(Tabela4[Estoque disponível],Tabela4[Material],Tabela29[[#This Row],[Material]]) -> 93.96 | F13: 11.88
B14: PI-01-012 | C14: 5085021400350595 | D14: CEREJA MIX - AROMA ARTIFICIAL DE | E14: =SUMIFS(Tabela4[Estoque disponível],Tabela4[Material],Tabela29[[#This Row],[Material]]) -> 111.6 | F14: 11.88
... B19: PI-01-017 | C19: 5085012300880595 | D19: BAUNILHA MIX - AROMA ARTIFICIAL | E19: =SUMIFS(Tabela4[Estoque disponível],Tabela4[Material],Tabela29[[#This Row],[Material]]) -> 250.92 | F19: 11.88
B21: CLASSIC | C21: Material | D21: Nome Material | E21: Saldo PIK | F21: Peso Min | G21: Prox/Atual | H21: Lote
B22: PH-01-027 | C22: 5053130800020584 | D22: BRANCO SOFTGEL CLASSIC - CORANTE ARTIF | E22: =SUMIFS(Tabela4[Estoque disponível],Tabela4[Material],Tabela9[[#This Row],[Material]]) -> 66.45 | F22: 12
B23: PH-01-028 | C23: 5053230600000584 | D23: CINZA SOFTGEL CLASSIC - CORANTE ARTIFI | E23: =SUMIFS(Tabela4[Estoque disponível],Tabela4[Material],Tabela9[[#This Row],[Material]]) -> 33.6 | F23: 12
B24: PH-01-029 | C24: 5053133800010584 | D24: ROXO SOFTGEL CLASSIC - CORANTE ARTIFIC | E24: =SUMIFS(Tabela4[Estoque disponível],Tabela4[Material],Tabela9[[#This Row],[Material]]) -> 21.45 | F24: 12
B25: PH-01-030 | C25: 5053130700010584 | D25: AZUL MARINHO SOFTGEL CLASSIC - CORANTE | E25: =SUMIFS(Tabela4[Estoque disponível],Tabela4[Material],Tabela9[[#This Row],[Material]]) -> 56.25 | F25: 12
B26: PH-01-031 | C26: 5053082000020584 | D26: VINHO SOFTGEL CLASSIC - CORANTE ARTIFI | E26: =SUMIFS(Tabela4[Estoque disponível],Tabela4[Material],Tabela9[[#This Row],[Material]]) -> 30.45 | F26: 12
B27: PH-01-032 | C27: 5053005200070584 | D27: AMARELO SOFTGEL CLASSIC - CORANTE ARTI | E27: =SUMIFS(Tabela4[Estoque disponível],Tabela4[Material],Tabela9[[#This Row],[Material]]) -> 33.3 | F27: 12
B28: PH-01-033 | C28: 5053230700000584 | D28: VERDE CLARO SOFTGEL CLASSIC - CORANTE | E28: =SUMIFS(Tabela4[Estoque disponível],Tabela4[Material],Tabela9[[#This Row],[Material]]) -> 50.25 | F28: 12
B29: PH-01-034 | C29: 5053045400030584 | D29: LARANJA SOFTGEL CLASSIC - CORANTE ARTI | E29: =SUMIFS(Tabela4[Estoque disponível],Tabela4[Material],Tabela9[[#This Row],[Material]]) -> 20.55 | F29: 12
B30: PH-01-036 | C30: 5053133000040584 | D30: MARROM SOFTGEL CLASSIC - CORANTE ARTIF | E30: =SUMIFS(Tabela4[Estoque disponível],Tabela4[Material],Tabela9[[#This Row],[Material]]) -> 56.25 | F30: 12
B31: PH-01-037 | C31: 5053133000040584 | D31: PRETO SOFTGEL CLASSIC - CORANTE ARTIFI | E31: =SUMIFS(Tabela4[Estoque disponível],Tabela4[Material],Tabela9[[#This Row],[Material]]) -> 56.25 | F31: 12
B32: PH-01-038 | C32: 5053134600020584 | D32: VERMELHO SOFTGEL CLASSIC - CORANTE ART | E32: =SUMIFS(Tabela4[Estoque disponível],Tabela4[Material],Tabela9[[#This Row],[Material]]) -> 80.85 | F32: 12
B33: PH-01-039 | C33: 5053071200030584 | D33: ROSA SOFTGEL CLASSIC - CORANTE ARTIFIC | E33: =SUMIFS(Tabela4[Estoque disponível],Tabela4[Material],Tabela9[[#This Row],[Material]]) -> 72.6 | F33: 12
... B36: PH-01-043 | C36: 5053230800000584 | D36: VERDE ESCURO SOFTGEL CLASSIC - CORANTE | E36: =SUMIFS(Tabela4[Estoque disponível],Tabela4[Material],Tabela9[[#This Row],[Material]]) -> 101.1 | F36: 12
B38: TINT | C38: Material | D38: Nome Material | E38: Saldo PIK | F38: Peso Min | G38: Prox/Atual | H38: Lote
B39: PH-01-003 | C39: 5053134600000593 | D39: VERMELHO CHOCO TINT - CORANTE ARTIFICI | E39: =SUMIFS(Tabela4[Estoque disponível],Tabela4[Material],Tabela96[[#This Row],[Material]]) -> 49.536 | F39: 9.504
B40: PH-01-004 | C40: 5053130300000593 | D40: AZUL CHOCO TINT - CORANTE ARTIFICIAL D | E40: =SUMIFS(Tabela4[Estoque disponível],Tabela4[Material],Tabela96[[#This Row],[Material]]) -> 60.912 | F40: 9.504
B41: PH-01-005 | C41: 5053130700020593 | D41: AZUL MARINHO CHOCO TINT - CORANTE ARTI | E41: =SUMIFS(Tabela4[Estoque disponível],Tabela4[Material],Tabela96[[#This Row],[Material]]) -> 26.352 | F41: 9.504
B42: PH-01-006 | C42: 5.0530712e+15 | D42: ROSA CHOCO TINT - CORANTE ARTIFICIAL D | E42: =SUMIFS(Tabela4[Estoque disponível],Tabela4[Material],Tabela96[[#This Row],[Material]]) -> 2.592 | F42: 9.504 | G42: J-04-012 | H42: 550087019
B43: PH-01-007 | C43: 5053133000010593 | D43: PRETO CHOCO TINT - CORANTE ARTIFICIAL | E43: =SUMIFS(Tabela4[Estoque disponível],Tabela4[Material],Tabela96[[#This Row],[Material]]) -> 34.704 | F43: 9.504
B44: PH-01-008 | C44: 5053127000000593 | D44: VERDE CHOCO TINT - CORANTE ARTIFICIAL | E44: =SUMIFS(Tabela4[Estoque disponível],Tabela4[Material],Tabela96[[#This Row],[Material]]) -> 63.072 | F44: 9.504
B45: PH-01-010 | C45: 5053005200000593 | D45: AMARELO CHOCO TINT - CORANTE ARTIFICIA | E45: =SUMIFS(Tabela4[Estoque disponível],Tabela4[Material],Tabela96[[#This Row],[Material]]) -> 53.424 | F45: 9.504
B46: PH-01-012 | C46: 5053045400000593 | D46: LARANJA CHOCO TINT - CORANTE ARTIFICIA | E46: =SUMIFS(Tabela4[Estoque disponível],Tabela4[Material],Tabela96[[#This Row],[Material]]) -> 35.136 | F46: 9.504
B47: PH-01-013 | C47: 5053133800020593 | D47: ROXO CHOCO TINT - CORANTE ARTIFICIAL D | E47: =SUMIFS(Tabela4[Estoque disponível],Tabela4[Material],Tabela96[[#This Row],[Material]]) -> 36.288 | F47: 9.504
